<?xml version="1.0" ?>
<!-- =================================================================================== -->
<!-- |    This document was autogenerated by xacro from mrm_xacro.xacro                | -->
<!-- |    EDITING THIS FILE BY HAND IS NOT RECOMMENDED                                 | -->
<!-- =================================================================================== -->
<robot name="my_rob1">
  <!-- Specify some colours -->
  <material name="white">
    <color rgba="1 1 1 1"/>
  </material>
  <material name="orange">
    <color rgba="1 0.3 0.1 1"/>
  </material>
  <material name="blue">
    <color rgba="0.2 0.2 1 1"/>
  </material>
  <gazebo reference="link_01">
    <material>Gazebo/Green</material>
  </gazebo>
  <gazebo reference="link_02">
    <material>Gazebo/Blue</material>
  </gazebo>
  <gazebo reference="link_03">
    <material>Gazebo/Orange</material>
  </gazebo>
  <gazebo reference="link_04">
    <material>Gazebo/Green</material>
  </gazebo>
  <gazebo reference="link_05">
    <material>Gazebo/Blue</material>
  </gazebo>
  <link name="base_link">
    <inertial>
      <mass value="200"/>
      <origin rpy="0 0 0" xyz="0 0 0.5"/>
      <inertia ixx="170.6" ixy="0" ixz="0" iyy="170.6" iyz="0" izz="170.6"/>
    </inertial>
    <collision>
      <origin rpy="0 0 0" xyz="0 0 0.5"/>
      <geometry>
        <box size="1 1 1"/>
      </geometry>
    </collision>
    <visual>
      <origin rpy="0 0 0" xyz="0 0 0.5"/>
      <geometry>
        <box size="1 1 1"/>
      </geometry>
      <material name="blue"/>
    </visual>
  </link>
  <joint name="base_link__link_01" type="revolute">
    <axis xyz="0 0 1"/>
    <limit effort="1000" lower="-3.14" upper="3.14" velocity="0.5"/>
    <origin rpy="0 0 0" xyz="0 0 1"/>
    <parent link="base_link"/>
    <child link="link_01"/>
  </joint>
  <transmission name="trans_base_link__link_01">
    <type> transmission_interface/SimpleTransmission </type>
    <joint name="base_link__link_01">
      <hardwareInterface> hardware_interface/EffortJointInterface </hardwareInterface>
    </joint>
    <actuator name="motor_base_link__link_01">
      <hardwareInterface> hardware_interface/EffortJointInterface </hardwareInterface>
      <mechanicalReduction> 1 </mechanicalReduction>
    </actuator>
  </transmission>
  <link name="link_01">
    <inertial>
      <mass value="1"/>
      <origin rpy="0 0 0" xyz="0 0 0.2"/>
      <inertia ixx="13.6" ixy="0" ixz="0" iyy="13.6" iyz="0" izz="9.6"/>
    </inertial>
    <collision>
      <origin rpy="0 0 0" xyz="0 0 0.2"/>
      <geometry>
        <cylinder length="0.4" radius="0.35"/>
      </geometry>
    </collision>
    <visual>
      <origin rpy="0 0 0" xyz="0 0 0.2"/>
      <geometry>
        <cylinder length="0.4" radius="0.35"/>
      </geometry>
      <material name="blue"/>
    </visual>
  </link>
  <joint name="link_01__link_02" type="revolute">
    <axis xyz="0 1 0"/>
    <limit effort="1000" lower="-1" upper="1" velocity="0.5"/>
    <origin rpy="0 0 0" xyz="0 0 0.4"/>
    <parent link="link_01"/>
    <child link="link_02"/>
  </joint>
  <transmission name="trans_link_01__link_02">
    <type> transmission_interface/SimpleTransmission </type>
    <joint name="link_01__link_02">
      <hardwareInterface> hardware_interface/EffortJointInterface </hardwareInterface>
    </joint>
    <actuator name="motor_link_01__link_02">
      <hardwareInterface> hardware_interface/EffortJointInterface </hardwareInterface>
      <mechanicalReduction> 1 </mechanicalReduction>
    </actuator>
  </transmission>
  <link name="link_02">
    <inertial>
      <mass value="1"/>
      <origin rpy="0 0 0" xyz="0 0 0.4"/>
      <inertia ixx="12.6" ixy="0" ixz="0" iyy="12.6" iyz="0" izz="0.6"/>
    </inertial>
    <collision>
      <origin rpy="0 0 0" xyz="0 0 0.4"/>
      <geometry>
        <cylinder length="0.8" radius="0.15"/>
      </geometry>
    </collision>
    <visual>
      <origin rpy="0 0 0" xyz="0 0 0.4"/>
      <geometry>
        <cylinder length="0.8" radius="0.15"/>
      </geometry>
      <material name="orange"/>
    </visual>
  </link>
  <joint name="link_02__link_03" type="revolute">
    <axis xyz="0 1 0"/>
    <limit effort="1000" lower="-1" upper="1" velocity="0.5"/>
    <origin rpy="0 0 0" xyz="0 0 0.8"/>
    <parent link="link_02"/>
    <child link="link_03"/>
  </joint>
  <transmission name="trans_link_02__link_03">
    <type> transmission_interface/SimpleTransmission </type>
    <joint name="link_02__link_03">
      <hardwareInterface> hardware_interface/EffortJointInterface </hardwareInterface>
    </joint>
    <actuator name="motor_link_02__link_03">
      <hardwareInterface> hardware_interface/EffortJointInterface </hardwareInterface>
      <mechanicalReduction> 1 </mechanicalReduction>
    </actuator>
  </transmission>
  <link name="link_03">
    <inertial>
      <mass value="1"/>
      <origin rpy="0 0 0" xyz="0 0 0.4"/>
      <inertia ixx="12.6" ixy="0" ixz="0" iyy="12.6" iyz="0" izz="0.6"/>
    </inertial>
    <collision>
      <origin rpy="0 0 0" xyz="0 0 0.4"/>
      <geometry>
        <cylinder length="0.8" radius="0.15"/>
      </geometry>
    </collision>
    <visual>
      <origin rpy="0 0 0" xyz="0 0 0.4"/>
      <geometry>
        <cylinder length="0.8" radius="0.15"/>
      </geometry>
      <material name="blue"/>
    </visual>
  </link>
  <joint name="link_03__link_04" type="revolute">
    <axis xyz="0 1 0"/>
    <limit effort="1000" lower="-1" upper="1" velocity="0.5"/>
    <origin rpy="0 0 0" xyz="0 0 0.8"/>
    <parent link="link_03"/>
    <child link="link_04"/>
  </joint>
  <transmission name="trans_link_03__link_04">
    <type> transmission_interface/SimpleTransmission </type>
    <joint name="link_03__link_04">
      <hardwareInterface> hardware_interface/EffortJointInterface </hardwareInterface>
    </joint>
    <actuator name="motor_link_03__link_04">
      <hardwareInterface> hardware_interface/EffortJointInterface </hardwareInterface>
      <mechanicalReduction> 1 </mechanicalReduction>
    </actuator>
  </transmission>
  <link name="link_04">
    <inertial>
      <mass value="1"/>
      <origin rpy="0 0 0" xyz="0 0 0.4"/>
      <inertia ixx="12.6" ixy="0" ixz="0" iyy="12.6" iyz="0" izz="0.6"/>
    </inertial>
    <collision>
      <origin rpy="0 0 0" xyz="0 0 0.4"/>
      <geometry>
        <cylinder length="0.8" radius="0.15"/>
      </geometry>
    </collision>
    <visual>
      <origin rpy="0 0 0" xyz="0 0 0.4"/>
      <geometry>
        <cylinder length="0.8" radius="0.15"/>
      </geometry>
      <material name="orange"/>
    </visual>
  </link>
  <joint name="link_04__link_05" type="revolute">
    <axis xyz="0 0 1"/>
    <limit effort="1000" lower="-3.14" upper="3.14" velocity="0.5"/>
    <origin rpy="0 0 0" xyz="0 0 0.8"/>
    <parent link="link_04"/>
    <child link="link_05"/>
  </joint>
  <transmission name="trans_link_04__link_05">
    <type> transmission_interface/SimpleTransmission </type>
    <joint name="link_04__link_05">
      <hardwareInterface> hardware_interface/EffortJointInterface </hardwareInterface>
    </joint>
    <actuator name="motor_link_04__link_05">
      <hardwareInterface> hardware_interface/EffortJointInterface </hardwareInterface>
      <mechanicalReduction> 1 </mechanicalReduction>
    </actuator>
  </transmission>
  <link name="link_05">
    <inertial>
      <mass value="1"/>
      <origin rpy="0 0 0" xyz="0 0 0.125"/>
      <inertia ixx="0.47" ixy="0" ixz="0" iyy="0.47" iyz="0" izz="0.2"/>
    </inertial>
    <collision>
      <origin rpy="0 0 0" xyz="0 0 0.125"/>
      <geometry>
        <cylinder length="0.25" radius="0.15"/>
      </geometry>
    </collision>
    <visual>
      <origin rpy="0 0 0" xyz="0 0 0.125"/>
      <geometry>
        <cylinder length="0.25" radius="0.15"/>
      </geometry>
      <material name="blue"/>
    </visual>
  </link>
  <gazebo>
    <plugin filename="libgazebo_ros_control.so" name="gazebo_ros_control">
        </plugin>
  </gazebo>
</robot>

